Workbook

Sheet Overview
B2: DESIGN OS — ASSET LIBRARY LOG
B5: Tracking 200–500 furniture & decor GLB assets sourced for the Three.js Design OS
B7: Target items | D7: Published | F7: In progress | H7: Backlog
B8: =COUNTA(Master!B:B)-1 -> 246 | D8: =COUNTIF(Master!N:N,"published") -> 0 | F8: =COUNTIF(Master!N:N,"pending")+COUNTIF(Master!N:N,"in-review") -> 36 | H8: =COUNTIF(Master!N:N,"backlog") -> 210
B12: Progress
B13: =B8/200 -> 1.23 | C13: (of 200 target — bump to 500 once 200 are published)
B15: Coverage by room
B16: Room | C16: Target | D16: Published | E16: % Done
B17: Kitchen | C17: 45 | D17: =COUNTIFS(Master!E:E,"*Kitchen*",Master!N:N,"published") -> 0 | E17: =IFERROR(D17/C17,0) -> 0
B18: Bedroom | C18: 35 | D18: =COUNTIFS(Master!E:E,"*Bedroom*",Master!N:N,"published") -> 0 | E18: =IFERROR(D18/C18,0) -> 0
B19: Living | C19: 40 | D19: =COUNTIFS(Master!E:E,"*Living*",Master!N:N,"published") -> 0 | E19: =IFERROR(D19/C19,0) -> 0
B20: Dining | C20: 20 | D20: =COUNTIFS(Master!E:E,"*Dining*",Master!N:N,"published") -> 0 | E20: =IFERROR(D20/C20,0) -> 0
B21: Bathroom | C21: 20 | D21: =COUNTIFS(Master!E:E,"*Bathroom*",Master!N:N,"published") -> 0 | E21: =IFERROR(D21/C21,0) -> 0
B22: Office | C22: 15 | D22: =COUNTIFS(Master!E:E,"*Office*",Master!N:N,"published") -> 0 | E22: =IFERROR(D22/C22,0) -> 0
B23: Kids | C23: 10 | D23: =COUNTIFS(Master!E:E,"*Kids*",Master!N:N,"published") -> 0 | E23: =IFERROR(D23/C23,0) -> 0
B24: Outdoor | C24: 10 | D24: =COUNTIFS(Master!E:E,"*Outdoor*",Master!N:N,"published") -> 0 | E24: =IFERROR(D24/C24,0) -> 0
B25: Lighting | C25: 30 | D25: =COUNTIFS(Master!E:E,"*Lighting*",Master!N:N,"published") -> 0 | E25: =IFERROR(D25/C25,0) -> 0
B26: Decor | C26: 25 | D26: =COUNTIFS(Master!E:E,"*Decor*",Master!N:N,"published") -> 0 | E26: =IFERROR(D26/C26,0) -> 0

Sheet Master
A1: # | B1: Asset ID | C1: Display name | D1: Group | E1: Room(s) | F1: Furniture type | G1: Style | H1: Variants | I1: Source | J1: Source URL | K1: License | L1: Format | M1: Hero? | N1: Status | O1: Notes / Next action
A2: 1 | B2: base_cabinet_600 | C2: Base Cabinet 600 | D2: Base Units | E2: Kitchen | F2: CABINET_BASE | G2: Modern | H2: 3 | I2: Sketchfab | K2: CC-BY | L2: glb | N2: backlog
A3: 2 | B3: base_cabinet_900 | C3: Base Cabinet 900 | D3: Base Units | E3: Kitchen | F3: CABINET_BASE | G3: Indian | H3: 3 | I3: Poly Haven | K3: CC0 | L3: glb | N3: backlog
A4: 3 | B4: base_cabinet_1200 | C4: Base Cabinet 1200 | D4: Base Units | E4: Kitchen | F4: CABINET_BASE | G4: Scandinavian | H4: 3 | I4: cgtips.org | K4: Free* | L4: skp | N4: backlog
A5: 4 | B5: pull_out_pantry_300 | C5: Pull-out Pantry 300 | D5: Base Units | E5: Kitchen | F5: CABINET_BASE | G5: Modern | H5: 3 | I5: 3D Warehouse | K5: Free* | L5: skp | N5: backlog
A6: 5 | B6: pull_out_pantry_450 | C6: Pull-out Pantry 450 | D6: Base Units | E6: Kitchen | F6: CABINET_BASE | G6: Indian | H6: 3 | I6: OpenSource3D | K6: CC0 | L6: glb | N6: backlog
A7: 6 | B7: corner_lazy_susan | C7: Corner Lazy Susan | D7: Base Units | E7: Kitchen | F7: CABINET_BASE | G7: Scandinavian | H7: 3 | I7: Sketchfab | K7: CC-BY | L7: glb | N7: backlog
A8: 7 | B8: 3_drawer_unit_600 | C8: 3-Drawer Unit 600 | D8: Drawer Units | E8: Kitchen | F8: CABINET_BASE | G8: Modern | H8: 3 | I8: Poly Haven | K8: CC0 | L8: glb | N8: pending
A9: 8 | B9: 3_drawer_unit_900 | C9: 3-Drawer Unit 900 | D9: Drawer Units | E9: Kitchen | F9: CABINET_BASE | G9: Indian | H9: 3 | I9: cgtips.org | K9: Free* | L9: skp | N9: backlog
A10: 9 | B10: cutlery_drawer_600 | C10: Cutlery Drawer 600 | D10: Drawer Units | E10: Kitchen | F10: CABINET_BASE | G10: Scandinavian | H10: 3 | I10: 3D Warehouse | K10: Free* | L10: skp | N10: backlog
A11: 10 | B11: pots__pans_drawer_900 | C11: Pots & Pans Drawer 900 | D11: Drawer Units | E11: Kitchen | F11: CABINET_BASE | G11: Modern | H11: 3 | I11: OpenSource3D | K11: CC0 | L11: glb | N11: backlog
A12: 11 | B12: deep_drawer_600 | C12: Deep Drawer 600 | D12: Drawer Units | E12: Kitchen | F12: CABINET_BASE | G12: Indian | H12: 3 | I12: Sketchfab | K12: CC-BY | L12: glb | N12: backlog
A13: 12 | B13: wall_cabinet_600 | C13: Wall Cabinet 600 | D13: Wall Units | E13: Kitchen | F13: CABINET_WALL | G13: Scandinavian | H13: 3 | I13: Poly Haven | K13: CC0 | L13: glb | N13: backlog
... A46: 45 | B46: breakfast_counter_top | C46: Breakfast Counter Top | D46: Breakfast Counter | E46: Kitchen | F46: CHAIR | G46: Scandinavian | H46: 1 | I46: OpenSource3D | K46: CC0 | L46: glb | N46: backlog
A47: 46 | B47: single_bed_1000 | C47: Single Bed 1000 | D47: Beds | E47: Bedroom | F47: BED | G47: Modern | H47: 3 | I47: Sketchfab | K47: CC-BY | L47: glb | M47: YES | N47: pending
A48: 47 | B48: king_bed_plain | C48: King Bed (Plain) | D48: Beds | E48: Bedroom | F48: BED | G48: Indian | H48: 3 | I48: Poly Haven | K48: CC0 | L48: glb | M48: YES | N48: backlog
A49: 48 | B49: king_bed_tufted | C49: King Bed (Tufted) | D49: Beds | E49: Bedroom | F49: BED | G49: Scandinavian | H49: 3 | I49: cgtips.org | K49: Free* | L49: skp | M49: YES | N49: backlog
A50: 49 | B50: king_bed_wingback | C50: King Bed (Wingback) | D50: Beds | E50: Bedroom | F50: BED | G50: Modern | H50: 3 | I50: 3D Warehouse | K50: Free* | L50: skp | M50: YES | N50: backlog
A51: 50 | B51: queen_bed_storage | C51: Queen Bed (Storage) | D51: Beds | E51: Bedroom | F51: BED | G51: Indian | H51: 3 | I51: OpenSource3D | K51: CC0 | L51: glb | M51: YES | N51: backlog
A52: 51 | B52: platform_bed_low | C52: Platform Bed Low | D52: Beds | E52: Bedroom | F52: BED | G52: Scandinavian | H52: 3 | I52: Sketchfab | K52: CC-BY | L52: glb | M52: YES | N52: backlog
A53: 52 | B53: four_poster_bed | C53: Four-Poster Bed | D53: Beds | E53: Bedroom | F53: BED | G53: Modern | H53: 3 | I53: Poly Haven | K53: CC0 | L53: glb | M53: YES | N53: backlog
A54: 53 | B54: bunk_bed_twin | C54: Bunk Bed Twin | D54: Beds | E54: Bedroom | F54: BED | G54: Indian | H54: 3 | I54: cgtips.org | K54: Free* | L54: skp | M54: YES | N54: backlog
A55: 54 | B55: sliding_wardrobe_2_door_1800 | C55: Sliding Wardrobe 2-door 1800 | D55: Wardrobes | E55: Bedroom | F55: WARDROBE | G55: Scandinavian | H55: 3 | I55: 3D Warehouse | K55: Free* | L55: skp | N55: backlog
A56: 55 | B56: sliding_wardrobe_3_door_2700 | C56: Sliding Wardrobe 3-door 2700 | D56: Wardrobes | E56: Bedroom | F56: WARDROBE | G56: Modern | H56: 3 | I56: OpenSource3D | K56: CC0 | L56: glb | N56: backlog
A57: 56 | B57: openable_wardrobe_4_door | C57: Openable Wardrobe 4-door | D57: Wardrobes | E57: Bedroom | F57: WARDROBE | G57: Indian | H57: 3 | I57: Sketchfab | K57: CC-BY | L57: glb | N57: backlog
A58: 57 | B58: walk_in_wardrobe_modular | C58: Walk-in Wardrobe Modular | D58: Wardrobes | E58: Bedroom | F58: WARDROBE | G58: Scandinavian | H58: 3 | I58: Poly Haven | K58: CC0 | L58: glb | N58: backlog
A59: 58 | B59: loft_wardrobe_top | C59: Loft Wardrobe Top | D59: Wardrobes | E59: Bedroom | F59: WARDROBE | G59: Modern | H59: 3 | I59: cgtips.org | K59: Free* | L59: skp | N59: backlog
A60: 59 | B60: bedside_table_1_drawer | C60: Bedside Table 1-Drawer | D60: Bedside | E60: Bedroom | F60: NIGHTSTAND | G60: Indian | H60: 1 | I60: 3D Warehouse | K60: Free* | L60: skp | N60: backlog
A61: 60 | B61: bedside_table_2_drawer | C61: Bedside Table 2-Drawer | D61: Bedside | E61: Bedroom | F61: NIGHTSTAND | G61: Scandinavian | H61: 1 | I61: OpenSource3D | K61: CC0 | L61: glb | N61: backlog
A62: 61 | B62: floating_nightstand | C62: Floating Nightstand | D62: Bedside | E62: Bedroom | F62: NIGHTSTAND | G62: Modern | H62: 1 | I62: Sketchfab | K62: CC-BY | L62: glb | N62: backlog
A63: 62 | B63: mid_century_nightstand | C63: Mid-century Nightstand | D63: Bedside | E63: Bedroom | F63: NIGHTSTAND | G63: Indian | H63: 1 | I63: Poly Haven | K63: CC0 | L63: glb | N63: backlog
A64: 63 | B64: industrial_nightstand | C64: Industrial Nightstand | D64: Bedside | E64: Bedroom | F64: NIGHTSTAND | G64: Scandinavian | H64: 1 | I64: cgtips.org | K64: Free* | L64: skp | N64: backlog
A65: 64 | B65: chest_of_drawers_5_drawer | C65: Chest of Drawers 5-drawer | D65: Dressers | E65: Bedroom | F65: DRESSER | G65: Modern | H65: 1 | I65: 3D Warehouse | K65: Free* | L65: skp | N65: backlog
A66: 65 | B66: 6_drawer_lowboy | C66: 6-drawer Lowboy | D66: Dressers | E66: Bedroom | F66: DRESSER | G66: Indian | H66: 1 | I66: OpenSource3D | K66: CC0 | L66: glb | N66: backlog
... A77: 76 | B77: bedroom_rug_6x9 | C77: Bedroom Rug 6x9 | D77: Bedroom Accent | E77: Bedroom | F77: CHAIR | G77: Modern | H77: 1 | I77: Sketchfab | K77: CC-BY | L77: glb | N77: backlog
A78: 77 | B78: 2_seater_sofa | C78: 2-Seater Sofa | D78: Sofas | E78: Living | F78: SOFA | G78: Indian | H78: 3 | I78: Poly Haven | K78: CC0 | L78: glb | M78: YES | N78: backlog
A79: 78 | B79: 3_seater_sofa | C79: 3-Seater Sofa | D79: Sofas | E79: Living | F79: SOFA | G79: Scandinavian | H79: 3 | I79: cgtips.org | K79: Free* | L79: skp | M79: YES | N79: backlog
A80: 79 | B80: 4_seater_sofa | C80: 4-Seater Sofa | D80: Sofas | E80: Living | F80: SOFA | G80: Modern | H80: 3 | I80: 3D Warehouse | K80: Free* | L80: skp | M80: YES | N80: pending
A81: 80 | B81: l_shape_sectional_left | C81: L-Shape Sectional Left | D81: Sofas | E81: Living | F81: SOFA | G81: Indian | H81: 3 | I81: OpenSource3D | K81: CC0 | L81: glb | M81: YES | N81: backlog
A82: 81 | B82: l_shape_sectional_right | C82: L-Shape Sectional Right | D82: Sofas | E82: Living | F82: SOFA | G82: Scandinavian | H82: 3 | I82: Sketchfab | K82: CC-BY | L82: glb | M82: YES | N82: backlog
...

Sheet Sources
B2: Asset Sources — ranked for our Three.js / R3F stack
B4: Rank | C4: Source | D4: Format | E4: Models | F4: License | G4: Auto-download? | H4: Notes
B5: 1 | C5: Sketchfab Download API | D5: GLB/GLTF | E5: 500,000+ | F5: CC-BY (most), CC0 (filter) | G5: YES — API+token | H5: PRIMARY. Real GLB exports. CC-BY OK if we credit author. Build script wrapper.
B6: 2 | C6: Poly Haven | D6: GLB | E6: ~150 (furn) | F6: CC0 | G6: YES — public URLs | H6: HERO TIER. Photoreal CC0 — best sofas/beds. Tiny library but quality is unmatched.
B7: 3 | C7: OpenSource3D / Meshy CC0 | D7: GLB/USDZ | E7: ~1,000 | F7: CC0 | G7: YES — direct download | H7: Solid fallback for generic objects. Quality varies — curate.
B8: 4 | C8: 3D Warehouse | D8: SKP (some GLB) | E8: millions | F8: 3DW Terms (free use ok with attribution) | G8: METADATA only | H8: Already integrated via scripts/catalog-scrape-3dw.mjs. Keep for thumbnails + Indian-style items not on Sketchfab.
B9: 5 | C9: sketchup.cgtips.org | D9: SKP | E9: 4,178+ | F9: Free personal+commercial (claimed) | G9: METADATA only | H9: AGGREGATOR of 3D Warehouse content. SKP only → requires SKP→GLB conversion (manual via SketchUp Pro or paid reaConverter). Use as reference / fallback only.
B10: 6 | C10: BlenderKit (free tier) | D10: BLEND/GLB | E10: ~10,000 | F10: Royalty-free (free tier) | G10: API w/ key | H10: Higher fidelity than CC0 sources. Worth a small $ spend later for hero pieces.
B11: 7 | C11: CGTrader Free | D11: GLB/FBX | E11: ~50,000 free | F11: Mixed (read each) | G11: Manual | H11: Quality is hit or miss. Use only when above sources lack a specific item.

Sheet Categories
B2: The 80% — what every home design needs
B4: Built from Infurnia + 3D Warehouse + Houzz category trees, filtered to the 20% of categories that cover 80% of designs. Each row maps to a "group" in src/data/catalog.ts.
B6: Room | C6: Group | D6: Sub-types | E6: Target items | F6: Hero pieces (priority) | G6: Indian/regional notes
B7: Kitchen | C7: Base / Drawer / Tall Units | D7: Modular cabinets, pull-outs, corner units | E7: 45 | F7: Hettich / Hafele inspired drawer units | G7: Indian: tandem boxes, magic-corner pull-outs are common
B8: Kitchen | C8: Appliances | D8: Hob, hood, fridge, microwave, dishwasher, RO unit | E8: 12 | F8: Chimney hood, fridge (double-door & SBS) | G8: Water purifier is essential in India (Aquaguard, Pureit)
B9: Kitchen | C9: Counter & Backsplash | D9: Quartz/granite slabs, tile backsplashes | E9: 5 | F9: Quartz countertop slab (Caesarstone-style) | G9: Granite countertops still dominate Indian kitchens
B10: Bedroom | C10: Beds | D10: Single, queen, king; storage, plain, tufted, four-poster | E10: 8 | F10: King with upholstered headboard | G10: Storage beds (hydraulic) are big in Indian apartments
B11: Bedroom | C11: Wardrobes | D11: Sliding 2/3-door, openable 4-door, walk-in, loft | E11: 5 | F11: 3-door sliding wardrobe 2700mm | G11: Loft cabinets above wardrobes — uniquely Indian
B12: Bedroom | C12: Bedside / Dresser | D12: Nightstand, chest of drawers, dressing table | E12: 11 | F12: Dressing table with mirror | G12: Pooja unit sometimes in master bedroom — consider
B13: Bedroom | C13: Accent | D13: Bench, full-length mirror, reading chair, bedroom rug | E13: 7 | F13: Reading nook chair + floor lamp pair | G13: Mosquito net frame? edge case
B14: Living | C14: Sofas | D14: 2/3/4-seat, L-section, U-section, recliner | E14: 10 | F14: 3-seater + L-section combo | G14: Diwan / settee for Indian living rooms
B15: Living | C15: Accent chairs | D15: Tub, wingback, slipper, cane lounge | E15: 6 | F15: Cane lounge chair (mid-century Indian) | G15: Cane and rattan are huge in modern Indian design
B16: Living | C16: Tables | D16: Coffee, side, console, nesting | E16: 7 | F16: Round wood coffee table + console | G16: Low-slung carved coffee tables for traditional homes
B17: Living | C17: TV / Media | D17: TV unit low/floor, media wall, display | E17: 4 | F17: Wall-mounted TV unit 2400mm | G17: Pooja niche sometimes integrates with TV wall
... B38: Decor | C38: Soft / Objects | D38: Pillows, blankets, vases, candles, books, baskets | E38: 14 | F38: Linen throw pillow set | G38: Brass artefacts add Indian character

Sheet Pipeline
B2: Ingestion Pipeline — from URL → Design OS catalog
B4: # | C4: Step | D4: What happens | E4: Tool / file | F4: Time
B5: 1 | C5: Pick from Categories sheet | D5: Choose the next batch (e.g. all "Sofas") from the 80% list | E5: Categories.xlsx | F5: ~5 min
B6: 2 | C6: Search by source priority | D6: Sketchfab (CC-BY/CC0) → Poly Haven → OpenSource3D → 3D Warehouse → cgtips | E6: sketchfab.com/search OR scripts/catalog-scrape-sketchfab.mjs (new) | F6: ~15 min / 10 items
B7: 3 | C7: Run automated scraper | D7: npm run catalog:scrape-sf -- --query "modern sofa" --license cc-by --limit 20 | E7: scripts/catalog-scrape-sketchfab.mjs | F7: ~10 min
B8: 4 | C8: Output → catalog-import.json | D8: JSON contains: title, source URL, thumbnail, downloadUrl, license, author | E8: catalog-import.json | F8: auto
B9: 5 | C9: Convert (if SKP) | D9: For SKP from 3DW/cgtips: open in SketchUp Pro → Export → glTF Binary (.glb). Or paid reaConverter for batch. | E9: manual or reaConverter CLI | F9: ~3 min per file
B10: 6 | C10: Open Catalog Admin | D10: In the app: Ribbon → Catalog Admin → "Import Scrape JSON" | E10: CatalogAdminModal.tsx | F10: ~30 sec
B11: 7 | C11: Attach GLB per item | D11: For each pending item: click → "Upload Model" → choose .glb. Stored in IndexedDB. | E11: putCatalogAsset() in lib/db.ts | F11: ~30 sec / item
B12: 8 | C12: Tune transform | D12: Set renderScale, renderRotation, renderOffset so item sits at floor + faces forward | E12: CatalogAdminModal.tsx | F12: ~1 min / item
B13: 9 | C13: Publish | D13: Click "Publish" → importStatus becomes "published" → item appears in CatalogSidebar | E13: CatalogAdminModal.tsx | F13: ~10 sec
B14: 10 | C14: Update this log | D14: Set Status=published in Master sheet, paste source URL | E14: Master sheet | F14: ~30 sec
